Workbook

Sheet Tổng hợp
A1: TỔNG HỢP KẾT QUẢ
A3: STT | B3: Tên màn hình/chức năng | C3: Số trường hợp kiểm thử đạt (P) | D3: Số trường hợp kiểm thử không đạt (F) | E3: Số trường hợp kiểm thử đang xem xét (PE) | F3: Số trường hợp kiểm thử chưa thực hiện | G3: Tổng số trường hợp kiểm thử | H3: Tỉ lệ trường hợp kiểm thử đạt (%P) | I3: Tỉ lệ trường hợp kiểm thử không đạt (%F) | J3: Tỉ lệ trường hợp kiểm thử đã thực hiện (%Cover)
A4: 1 | B4: 1. Đăng nhập/ đăng xuất | C4: ='1. Đăng nhập đăng xuất '!D4 | D4: ='1. Đăng nhập đăng xuất '!D5 | E4: 0 | F4: 0 | G4: ='1. Đăng nhập đăng xuất '!D8 | H4: =C4/G4 | I4: =D4/G4 | J4: =(C4+D4)/G4
A5: 2 | B5: 2. Splash screen | C5: ='2. Splash screen'!D4 | D5: 0 | E5: 0 | F5: 0 | G5: ='2. Splash screen'!D8 | H5: =C5/G5 | I5: =D5/G5 | J5: =(C5+D5)/G5
A6: 3 | B6: 3. Servey đăng nhập | C6: ='3. Survey đăng nhập'!D8 | D6: 0 | E6: 0 | F6: 0 | G6: ='3. Survey đăng nhập'!D8 | H6: =C6/G6 | I6: =D6/G6 | J6: =(C6+D6)/G6
A7: 4 | B7: 4. Màn hình home | C7: =Home!D4 | D7: 0 | E7: 0 | F7: 0 | G7: =Home!D8 | H7: =C7/G7 | I7: =D7/G7 | J7: =(C7+D7)/G7
A8: 5 | B8: 5. Màn hình quan tâm | C8: ='5. Màn hình quan tâm'!D4 | D8: 0 | E8: 0 | F8: 0 | G8: ='5. Màn hình quan tâm'!D8 | H8: =C8/G8 | I8: =D8/G8 | J8: =(C8+D8)/G8
A9: 6 | B9: 6. Abount/Unitel | C9: ='6.AboutUnitel'!D4 | D9: 0 | E9: 0 | F9: 0 | G9: ='6.AboutUnitel'!D8 | H9: =C9/G9 | I9: =D9/G9 | J9: =(C9+D9)/G9
A10: 7 | B10: 7. Thông báo | C10: ='7. Thông báo '!D4 | D10: 0 | E10: 0 | F10: 0 | G10: ='7. Thông báo '!D8 | H10: =C10/G10 | I10: =D10/G10 | J10: =(C10+D10)/G10
A11: 8 | B11: 8. Tài khoản | C11: ='8. Tài khoản'!D4 | D11: 0 | E11: 0 | F11: 0 | G11: ='8. Tài khoản'!D8 | H11: =C11/G11 | I11: =D11/G11 | J11: =(C11+D11)/G11
A12: 9 | B12: 9. Bộ giải pháp phổ biến | C12: ='9. Bộ giải pháp phổ biến'!D4 | D12: 0 | E12: 0 | F12: 0 | G12: ='9. Bộ giải pháp phổ biến'!D8 | H12: =C12/G12 | I12: =D12/G12 | J12: =(C12+D12)/G12
A13: 10 | B13: 10. Quản lý bộ giải pháp theo lĩnh vực | C13: ='10.Bộ giải pháp theo lĩnh vực '!D4 | D13: 0 | E13: 0 | F13: 0 | G13: ='10.Bộ giải pháp theo lĩnh vực '!D8 | H13: =C13/G13 | I13: =D13/G13 | J13: =(C13+D13)/G13
A14: 11 | B14: 11. Apps của tôi | C14: ='11. Apps của tôi'!D4 | D14: 0 | E14: 0 | F14: 0 | G14: ='11. Apps của tôi'!D8 | H14: =C14/G14 | I14: =D14/G14 | J14: =(C14+D14)/G14
A15: 12 | B15: 12. Term&Condition | C15: ='12. Term & Condition'!D4 | D15: 0 | E15: 0 | F15: 0 | G15: ='12. Term & Condition'!D8 | H15: =C15/G15 | I15: =D15/G15 | J15: =(C15+D15)/G15
A16: Total | C16: =SUM(C4:C11) | D16: =SUM(D4:D11) | E16: =SUM(E4:E11) | F16: =SUM(F4:F11) | G16: =SUM(G4:G11) | H16: =C16/G16 | I16: =D16/G16 | J16: =(C16+D16)/G16

Sheet 1. Đăng nhập đăng xuất 
C1: KỊCH BẢN KIỂM THỬ *
C2: Tên màn hình/Tên chức năng | D2: Đăng nhập/ đăng xuất
C3: Mã trường hợp kiểm thử | D3: WBS-1
C4: Số trường hợp kiểm thử đạt (P) | D4: =COUNTIF($Q$12:$Q$993,"P")
C5: Số trường hợp kiểm thử không đạt (F) | D5: =COUNTIF($Q$12:$Q$993,"F")
C6: Số trường hợp kiểm thử đang xem xét (PE) | D6: =COUNTIF($Q$12:$Q$993,"PE")
C7: Số trường hợp kiểm thử chưa thực hiện | D7: =D8-D4-D5-D6
C8: Tổng số trường hợp kiểm thử | D8: =COUNTA($D$13:$D$993)
A10: Mã test case | B10: Mục đích kiểm thử | C10: Các bước thực hiện | D10: Kết quả mong muốn | E10: Android | H10: IOS | K10: <Tên trình duyệt 3> | N10: <Tên trình duyệt 4> | Q10: Kết quả hiện tại | R10: Mã lỗi | S10: Ghi chú | T10: Ngày test | U10: Người test
E11: Lần 1 | F11: Lần 2 | G11: Lần 3 | H11: Lần 1 | I11: Lần 2 | J11: Lần 3 | K11: Lần 1 | L11: Lần 2 | M11: Lần 3 | N11: Lần 1 | O11: Lần 2 | P11: Lần 3
A12: =IF(AND(D12="",D12=""),"",$D$3&"_"&ROW()-11-COUNTBLANK($D$12:D12)) | B12: WBS 1.19: MÀN HÌNH ĐĂNG NHẬP
A13: =IF(AND(D13="",D13=""),"",$D$3&"_"&ROW()-11-COUNTBLANK($D$12:D13)) | B13: Tiền điều kiện | C13: • Người dùng đã cài đặt ứng dụng LaoOne. • Thiết bị có kết nối Internet.
A14: =IF(AND(D14="",D14=""),"",$D$3&"_"&ROW()-11-COUNTBLANK($D$12:D14)) | B14: Giao diện
A15: =IF(AND(D15="",D15=""),"",$D$3&"_"&ROW()-11-COUNTBLANK($D$12:D15)) | B15: Giao diện chung màn hình đăng nhập
A16: =IF(AND(D16="",D16=""),"",$D$3&"_"&ROW()-11-COUNTBLANK($D$12:D16)) | B16: Kiểm tra giao diện màn hình Login | C16: 1. Tại màn hình Login 2. Kiểm tra hiển thị | D16: 1. Hiển thị màn hình: - Tiêu đề Đăng nhập - Button chọn ngôn ngữ - Trường nhập Email/Số điện thoại - Button "Tiếp tục" - Button "Xác thực khuôn mặt" - Button đăng nhập với bên thứ 3 "Facebook/ Apple/ Google" - Button "Đăng nhập với vai trò là khách" - Điều khoản và chính sách | E16: P | H16: P | Q16: P
A17: =IF(AND(D17="",D17=""),"",$D$3&"_"&ROW()-11-COUNTBLANK($D$12:D17)) | C17: 3. Kiểm tra tổng thể giao diện: font chữ, chính tả, title... | D17: 2. Font chữ, cỡ chữ, màu sắc chữ, độ rộng cột, độ rộng hàng, màu sắc background, icon, vị trí icon, title, khoảng cách giữa các đối tượng hiển thị,... đúng với thiết kế | E17: P | H17: P | Q17: P
A18: =IF(AND(D18="",D18=""),"",$D$3&"_"&ROW()-11-COUNTBLANK($D$12:D18)) | C18: 4. Kiểm tra responsive | D18: 3. Thay đổi độ phân giải chuẩn khác nhau, màn hình và các control tuân thủ đúng nguyên tắc responsive, không bị vỡ cấu trúc | E18: P | H18: P | Q18: P
A19: =IF(AND(D19="",D19=""),"",$D$3&"_"&ROW()-11-COUNTBLANK($D$12:D19)) | C19: Hình ảnh | E19: P | H19: P | Q19: P
A20: =IF(AND(D20="",D20=""),"",$D$3&"_"&ROW()-11-COUNTBLANK($D$12:D20)) | B20: Kiểm tra hiển thị khi xoay màn hình theo chiều dọc/chiều ngang | C20: 1. Tại màn hình Login 2. Kiểm tra hiển thị 3. Bật tính năng xoay màn hình của thiết bị 4. Xoay ngang/dọc màn hình | D20: 1. Không di chuyển, giữ nguyên vùng màn hình | E20: P | H20: P | Q20: P
A21: =IF(AND(D21="",D21=""),"",$D$3&"_"&ROW()-11-COUNTBLANK($D$12:D21)) | B21: Kiểm tra giao diện khi scroll lên/xuống | C21: 1. Tại màn hình Login 2. Srcoll lên/xuống | D21: 1. Không có scroll | E21: P | H21: P | Q21: P
A22: =IF(AND(D22="",D22=""),"",$D$3&"_"&ROW()-11-COUNTBLANK($D$12:D22)) | B22: Kiểm tra giao diện ở trường hợp ngắt kết nối mạng | C22: 1. Ngắt kết nối mạng 2. Kết nối lại mạng | D22: 1. Hiển thị giao diện ngoại tuyến, thông báo "Không tìm thấy kết nối Internet. Kiểm tra kết nối của bạn hoặc thử lại." 2. Hiển thị giao diện màn hình login | E22: P | H22: P | Q22: P
A23: =IF(AND(D23="",D23=""),"",$D$3&"_"&ROW()-11-COUNTBLANK($D$12:D23)) | B23: Kiểm tra hiển thị tiêu đề Đăng nhập | C23: 1. Tại màn hình đăng nhập 2. Kiểm tra hiển thị text Tiêu đề | D23: 2. Giao diện hiển thị như figma | E23: P | H23: P | Q23: P
A24: =IF(AND(D24="",D24=""),"",$D$3&"_"&ROW()-11-COUNTBLANK($D$12:D24)) | B24: Kiểm tra hiển thị button Chọn ngôn ngữ | C24: 1. Tại màn hình đăng nhập 2. Kiểm tra hiển thị button | D24: 1. Căn bên phải màn, có hình cờ và viết tắt của ngôn ngữ, giao diện như figma | E24: P | H24: P | Q24: P
A25: =IF(AND(D25="",D25=""),"",$D$3&"_"&ROW()-11-COUNTBLANK($D$12:D25)) | B25: Kiểm tra hiển thị Trường nhập Email/Số điện thoại | C25: 1. Tại màn hình đăng nhập 2. Kiểm tra giao diện hiển thị | D25: 2. Hiển thị kích thước, vị trí như figma | E25: P | H25: P | Q25: P
A26: =IF(AND(D26="",D26=""),"",$D$3&"_"&ROW()-11-COUNTBLANK($D$12:D26)) | C26: 3. Kiểm tra placeholder | D26: 3. Hiển thị placeholder "Email/Số điện thoại" | E26: P
A27: =IF(AND(D27="",D27=""),"",$D$3&"_"&ROW()-11-COUNTBLANK($D$12:D27)) | B27: Kiểm tra hiển thị Nút xác thực bằng khuôn mặt/vân tay | C27: 1. Tại màn hình đăng nhập 2. Kiểm tra hiển thị nút | D27: 2. Căn bên phải, cạnh nút tiếp tục. giao diện hiển thị như figma | E27: P | H27: P | Q27: P
A28: =IF(AND(D28="",D28=""),"",$D$3&"_"&ROW()-11-COUNTBLANK($D$12:D28)) | B28: Kiểm tra click nút Xác thực bằng khuôn mặt | C28: 1. Tại màn hình đăng nhập 2. Kiểm tra click nút | D28: 1. Hiển thị khung để xác thực khuôn mặt | E28: P | H28: P | Q28: P
A29: =IF(AND(D29="",D29=""),"",$D$3&"_"&ROW()-11-COUNTBLANK($D$12:D29)) | B29: Kiểm tra click vào từng button đăng nhập bằng bên thứ 3 | C29: 1. Tại màn hình đăng nhập 2.Click lựa chọn phương thức 3. Kiếm tra hiển thị | D29: 3. Hệ thống chuyển hướng tới nền tảng xác thực tương ứng | E29: P | H29: P | Q29: P
A30: =IF(AND(D30="",D30=""),"",$D$3&"_"&ROW()-11-COUNTBLANK($D$12:D30)) | B30: Kiểm tra click "Đăng nhập với vai trò là khách" | C30: 1. Tại màn hình đăng nhập 2. Click vào dòng "Đăng nhập vói vai trò là khách" | D30: 1. Hệ thống điều hướng đến màn Trang chủ | E30: P | H30: P | Q30: P
A31: =IF(AND(D31="",D31=""),"",$D$3&"_"&ROW()-11-COUNTBLANK($D$12:D31)) | B31: Kiểm tra hiển thị nút "Tiếp tục" | C31: 1. Tại màn hình đăng nhập 2. Kiểm tra hiển thị nút "Tiếp tục" | D31: 1. Hiển thị mặc định là disable 2. Màu sắc, kích thước như figma | E31: P | H31: P
A32: =IF(AND(D32="",D32=""),"",$D$3&"_"&ROW()-11-COUNTBLANK($D$12:D32)) | B32: Kiểm tra khi click vào Điều khoản | C32: 1. Tại màn hình Đăng nhập 2. Click vào Điều khoản | D32: 2. Hệ thống điều hướng đến màn hình Điều khoản Laoone | E32: P | H32: P
A33: =IF(AND(D33="",D33=""),"",$D$3&"_"&ROW()-11-COUNTBLANK($D$12:D33)) | B33: Kiểm tra khi click vào Chính sách | C33: 1. Tại màn hình Đăng nhập 2. Click vào Chính sách | D33: 2. Hệ thống điều hướng đến màn hình Chính sách bảo mật Laoone | E33: P | H33: P
A34: =IF(AND(D34="",D34=""),"",$D$3&"_"&ROW()-11-COUNTBLANK($D$12:D34)) | B34: Validate Email
A35: =IF(AND(D35="",D35=""),"",$D$3&"_"&ROW()-11-COUNTBLANK($D$12:D35)) | B35: Kiểm tra nhập email hợp lệ có kí tự "@" và "." | C35: 1. Tại màn hình đăng nhập 2. Nhập email hợp lệ có đầy đủ tên email, tên miền, ký tự "@" và ký tự "." | D35: 1. Nút "Tiếp tục" hiển thị enable | E35: P | H35: P | Q35: P
A36: =IF(AND(D36="",D36=""),"",$D$3&"_"&ROW()-11-COUNTBLANK($D$12:D36)) | B36: Kiểm tra nhập email sai dịnh dạng: có các kí tự đặc biệt trước @ | C36: 1. Tại màn hình đăng nhập 2. Nhập email với các kí tự đặc biệt trước @: .>?#$%^& | D36: 1. Hiển thị lỗi " Email không hợp lệ" | E36: P | H36: P | Q36: P
A37: =IF(AND(D37="",D37=""),"",$D$3&"_"&ROW()-11-COUNTBLANK($D$12:D37)) | B37: Kiểm tra nhập email sai dịnh dạng: có các kí tự đặc biệt sau@ | C37: 1. Tại màn hình đăng nhập 2. Nhập email với các kí tự đặc biệt sau @: .>?#$%^& | D37: 1. Hiển thị lỗi " Email không hợp lệ" | E37: P | H37: P | Q37: P
A38: =IF(AND(D38="",D38=""),"",$D$3&"_"&ROW()-11-COUNTBLANK($D$12:D38)) | B38: Kiểm tra nhập email sai dịnh dạng: có chứa chữ có dấu | C38: 1. Tại màn hình đăng nhập 2. Nhập email có chứa chữ có dấu Vd: êfub@gmail.com | D38: 1. Hiển thị lỗi " Email không hợp lệ" | E38: P | H38: P | Q38: P
A39: =IF(AND(D39="",D39=""),"",$D$3&"_"&ROW()-11-COUNTBLANK($D$12:D39)) | B39: Kiểm tra nhập email sai dịnh dạng: có chứa khoảng trắng | C39: 1. Tại màn hình đăng nhập 2. Nhập email có chứa khoảng trắng | D39: 1. Hiển thị lỗi " Email không hợp lệ" | E39: P | H39: P | Q39: P
A40: =IF(AND(D40="",D40=""),"",$D$3&"_"&ROW()-11-COUNTBLANK($D$12:D40)) | B40: Kiểm tra email username trong khoảng [6-50] | C40: 1. Nhập email hợp lệ có độ dài là 6 | D40: 1. Nút "Tiếp tục" hiển thị enabe | E40: P | H40: P | Q40: P
A41: =IF(AND(D41="",D41=""),"",$D$3&"_"&ROW()-11-COUNTBLANK($D$12:D41)) | C41: 1. Nhập email hợp lệ có độ dài là 50 | D41: 1. Nút "Tiếp tục" hiển thị enabe | E41: P | H41: P | Q41: P
...

Sheet 2. Splash screen
C1: KỊCH BẢN KIỂM THỬ *
C2: Tên màn hình/Tên chức năng | D2: Splash screen
C3: Mã trường hợp kiểm thử | D3: WBS-2
C4: Số trường hợp kiểm thử đạt (P) | D4: =COUNTIF($Q$12:$Q$1022,"P")
C5: Số trường hợp kiểm thử không đạt (F) | D5: =COUNTIF($Q$12:$Q$1022,"F")
C6: Số trường hợp kiểm thử đang xem xét (PE) | D6: =COUNTIF($Q$12:$Q$1022,"PE")
C7: Số trường hợp kiểm thử chưa thực hiện | D7: =D8-D4-D5-D6
C8: Tổng số trường hợp kiểm thử | D8: =COUNTA($D$13:$D$1022)
A10: Mã test case | B10: Mục đích kiểm thử | C10: Các bước thực hiện | D10: Kết quả mong muốn | E10: Android | H10: IOS | K10: <Tên trình duyệt 3> | N10: <Tên trình duyệt 4> | Q10: Kết quả hiện tại | R10: Mã lỗi | S10: Ghi chú | T10: Ngày test | U10: Người test
E11: Lần 1 | F11: Lần 2 | G11: Lần 3 | H11: Lần 1 | I11: Lần 2 | J11: Lần 3 | K11: Lần 1 | L11: Lần 2 | M11: Lần 3 | N11: Lần 1 | O11: Lần 2 | P11: Lần 3
A12: =IF(AND(D12="",D12=""),"",$D$3&"_"&ROW()-11-COUNTBLANK($D$12:D12)) | B12: WBS 2.5: MÀN HÌNH SPLASH SCREEN
A13: =IF(AND(D13="",D13=""),"",$D$3&"_"&ROW()-11-COUNTBLANK($D$12:D13)) | B13: Tiền điều kiện | C13: • Người dùng đã cài đặt ứng dụng LaoOne. • Thiết bị có kết nối Internet. (app không có trong bộ nhớ đệm)
A14: =IF(AND(D14="",D14=""),"",$D$3&"_"&ROW()-11-COUNTBLANK($D$12:D14)) | B14: Giao diện
A15: =IF(AND(D15="",D15=""),"",$D$3&"_"&ROW()-11-COUNTBLANK($D$12:D15)) | B15: Giao diện chung
A16: =IF(AND(D16="",D16=""),"",$D$3&"_"&ROW()-11-COUNTBLANK($D$12:D16)) | B16: Kiểm tra hiển thị splash khi mở app | C16: 1. Tap mở app từ màn hình điện thoại | D16: 1. Hiển thị splash ngay lập tức | E16: P | H16: P | Q16: P
A17: =IF(AND(D17="",D17=""),"",$D$3&"_"&ROW()-11-COUNTBLANK($D$12:D17)) | B17: Kiểm tra animation nền | C17: 1. Quan sát sau khi mở app | D17: 1. Hiển thị hiệu ứng ánh sáng rọi từ trên xuống 2. Hiển thị đúng màu sắc như ở Figma | E17: P | H17: P | Q17: P
A18: =IF(AND(D18="",D18=""),"",$D$3&"_"&ROW()-11-COUNTBLANK($D$12:D18)) | B18: Kiểm tra hiển thị logo | C18: 1. Quan sát sau khi mở app | D18: 1. Hiển thị hiệu ứng ánh sáng rõ dần 2. Màu sắc các chữ cái hiển thị như figma: chữ O có 2 màu xanh và vàng, 4 chữ cái còn lại màu bạc 3. Text căn đúng vị trí, không lệch giữa các thiết bị | E18: P | H18: P | Q18: P
A19: =IF(AND(D19="",D19=""),"",$D$3&"_"&ROW()-11-COUNTBLANK($D$12:D19)) | C19: 1. Quan sát sau khi mở app | D19: 1. Trình tự hiển thị logo: - Chữ O hiển thị đầu tiên - Chữ LA hiển thị dần sau khi chữ O đã hiển thị - Cuối cùng hiển thị hai chữ NE | E19: P | H19: P | Q19: P
A20: =IF(AND(D20="",D20=""),"",$D$3&"_"&ROW()-11-COUNTBLANK($D$12:D20)) | C20: Hình ảnh | E20: P | H20: P | Q20: P
A21: =IF(AND(D21="",D21=""),"",$D$3&"_"&ROW()-11-COUNTBLANK($D$12:D21)) | B21: Kiểm tra xoay ngang màn hình | C21: 1. Quan sát sau khi mở app | D21: 1. Splash hiển thị responsive theo màn | E21: P | H21: P | Q21: P
A22: =IF(AND(D22="",D22=""),"",$D$3&"_"&ROW()-11-COUNTBLANK($D$12:D22)) | B22: Kiểm tra với dark mode/ light mode của điện thoại | C22: 1. Quan sát sau khi mở app | D22: 1. Splash không bị ảnh hưởng | E22: P | H22: P | Q22: P
A23: =IF(AND(D23="",D23=""),"",$D$3&"_"&ROW()-11-COUNTBLANK($D$12:D23)) | B23: Kiểm tra thứ tự hiển thị màn hình Splash | C23: 1. Quan sát hiển thị | D23: 1. Hiển thị đúng trình tự: - Luồng sáng màu vàng và xanh từ 2 bên màn hình - Chữ O với 2 nửa màu xanh và vàng được tạo thành - Có đổ bóng dưới logo - Hiển thị đầy đủ text Laone | E23: P | H23: P | Q23: P
A24: =IF(AND(D24="",D24=""),"",$D$3&"_"&ROW()-11-COUNTBLANK($D$12:D24)) | B24: Kiểm tra thoát giữa splash | C24: 1. Quan sát hiển thị | D24: 1. Không crash 2. Khi vào lại app hiển thị tiếp nối splash khi out | E24: P | H24: P | Q24: P
A25: =IF(AND(D25="",D25=""),"",$D$3&"_"&ROW()-11-COUNTBLANK($D$12:D25)) | B25: Kiểm tra điều hướng sau splash | C25: 1. Quan sát hiển thị | D25: 1. Người dùng được đưa tới màn đăng nhập 2. Mặc định ở chế độ sáng 3. Transition mượt, không giật lag, không có độ trễ | E25: P | H25: P | Q25: P
A26: =IF(AND(D26="",D26=""),"",$D$3&"_"&ROW()-11-COUNTBLANK($D$12:D26)) | B26: Kiểm tra hiển thị animation | C26: 1. Quan sát hiển thị | D26: 1. Hiệu ứng hiển thị mượt, chạy liên tục, không bị đóng băng giữa chừng, đủ các frame 2. Không giật lag, reset đột ngột | E26: P | H26: P | Q26: P
A27: =IF(AND(D27="",D27=""),"",$D$3&"_"&ROW()-11-COUNTBLANK($D$12:D27)) | B27: Kiểm tra hiển thị animation khi không có kết nối mạng | C27: 1. Quan sát hiển thị | D27: 1. Hiệu ứng hiển thị mượt, không bị dừng, không crash, giật lag | E27: P | H27: P | Q27: P

Sheet 3. Survey đăng nhập
C1: KỊCH BẢN KIỂM THỬ *
C2: Tên màn hình/Tên chức năng | D2: Surbvey đăng nhập
C3: Mã trường hợp kiểm thử | D3: WBS-3
C4: Số trường hợp kiểm thử đạt (P) | D4: =COUNTIF($Q$12:$Q$882,"P")
C5: Số trường hợp kiểm thử không đạt (F) | D5: =COUNTIF($Q$12:$Q$882,"F")
C6: Số trường hợp kiểm thử đang xem xét (PE) | D6: =COUNTIF($Q$12:$Q$882,"PE")
C7: Số trường hợp kiểm thử chưa thực hiện | D7: =D8-D4-D5-D6
C8: Tổng số trường hợp kiểm thử | D8: =COUNTA($D$12:$D$882)
A10: Mã test case | B10: Mục đích kiểm thử | C10: Các bước thực hiện | D10: Kết quả mong muốn | E10: Android | H10: IOS | K10: <Tên trình duyệt 3> | N10: <Tên trình duyệt 4> | Q10: Kết quả hiện tại | R10: Ghi chú | S10: Ngày test | T10: Người test
E11: Lần 1 | F11: Lần 2 | G11: Lần 3 | H11: Lần 1 | I11: Lần 2 | J11: Lần 3 | K11: Lần 1 | L11: Lần 2 | M11: Lần 3 | N11: Lần 1 | O11: Lần 2 | P11: Lần 3
A12: =IF(AND(D12="",D12=""),"",$D$3&"_"&ROW()-11-COUNTBLANK($D$12:D12)) | B12: WBS 3.8: MÀN HÌNH SURVEY ĐĂNG NHẬP
A13: =IF(AND(D13="",D13=""),"",$D$3&"_"&ROW()-11-COUNTBLANK($D$12:D13)) | B13: Tiền điều kiện | C13: Người dùng đã đăng nhập thành công
A14: =IF(AND(D14="",D14=""),"",$D$3&"_"&ROW()-11-COUNTBLANK($D$12:D14)) | B14: Survey step 1
A15: =IF(AND(D15="",D15=""),"",$D$3&"_"&ROW()-11-COUNTBLANK($D$12:D15)) | B15: Giao diện
A16: =IF(AND(D16="",D16=""),"",$D$3&"_"&ROW()-11-COUNTBLANK($D$12:D16)) | B16: Giao diện chung
A17: =IF(AND(D17="",D17=""),"",$D$3&"_"&ROW()-11-COUNTBLANK($D$12:D17)) | B17: Kiểm tra giao diện hiển thị màn Survey | C17: 1. Tại màn hình Survey 2. Kiểm tra hiển thị | D17: 1. Hiển thị màn hình: - Thanh tiến trình - Phân trang - Tiêu đề "Thông tin về bạn" +mô tả - Textbox: Họ tên, Số điện thoại, đơn vị, địa chỉ - Button "Xác nhận/ Bỏ qua" | E17: P | H17: P | Q17: P
A18: =IF(AND(D18="",D18=""),"",$D$3&"_"&ROW()-11-COUNTBLANK($D$12:D18)) | C18: Hình ảnh | E18: P | H18: P | Q18: P
A19: =IF(AND(D19="",D19=""),"",$D$3&"_"&ROW()-11-COUNTBLANK($D$12:D19)) | B19: Kiểm tra tổng thể giao diện màn hình | C19: 1. Kiểm tra chính tả, bố cục, màu chữ, font chữ | D19: 1. Đúng chính tả, bố cục tương xứng, màu sắc, font chữ với prototype | E19: P | H19: P | Q19: P
A20: =IF(AND(D20="",D20=""),"",$D$3&"_"&ROW()-11-COUNTBLANK($D$12:D20)) | C20: Kiểm tra label, textbox, button , lỗi chính tả | D20: 1. Các label, textbox có độ dài, rộng và khoảng cách bằng nhau, không xô lệch 2. Các label sử dụng cùng 1 loại font, cỡ chữ, căn lề trái 3. Kiểm tra tất cả lỗi về chính tả, cấu trúc câu, ngữ pháp | E20: P | H20: P | Q20: P
A21: =IF(AND(D21="",D21=""),"",$D$3&"_"&ROW()-11-COUNTBLANK($D$12:D21)) | C21: 1. Trượt lên, trượt xuống | D21: 1. Màn hình tương ứng và không bị vỡ giao diện. | E21: P | H21: P | Q21: P
A22: =IF(AND(D22="",D22=""),"",$D$3&"_"&ROW()-11-COUNTBLANK($D$12:D22)) | B22: Kiểm tra hiển thị giao diện trong khung màn hình (không tràn, không scroll ngang) | C22: 1. Tại màn hình Survey 2. Quan sát giao diện ở độ phân giải màn hình tiêu chuẩn | D22: 2. Toàn bộ nội dung hiển thị trong khung màn hình - Không có thành phần UI nào bị tràn khung hoặc che khuất - Không xuất hiện thanh scroll ngang | E22: P | H22: P | Q22: P
A23: =IF(AND(D23="",D23=""),"",$D$3&"_"&ROW()-11-COUNTBLANK($D$12:D23)) | B23: Kiểm tra hiển thị khi ngắt kết nối mạng | C23: 1. Tại màn hình Survey 2. Ngắt kết nối mạng | D23: 2. Hiển thị thông báo "Không thể kết nối đến máy chủ. Vui lòng kiểm tra lại kết nối" | E23: P | H23: P | Q23: P
A24: =IF(AND(D24="",D24=""),"",$D$3&"_"&ROW()-11-COUNTBLANK($D$12:D24)) | B24: Kiểm tra hiển thị khi kết nối lại mạng | C24: 1. Tại màn hình Survey 2. Kết nối lại mạng | D24: 2. Load tiếp trang và hiểu thị giao diện Trang chủ | E24: P | H24: P | Q24: P
A25: =IF(AND(D25="",D25=""),"",$D$3&"_"&ROW()-11-COUNTBLANK($D$12:D25)) | B25: Kiểm tra hiển thị nút Quay lại | C25: 1. Tại màn hình Survey 2. Kiểm tra hiển thị | D25: 1. Hiển thị kích thước, màu sắc như figma | E25: P | H25: P | Q25: P
A26: =IF(AND(D26="",D26=""),"",$D$3&"_"&ROW()-11-COUNTBLANK($D$12:D26)) | B26: Kiểm tra hiển thị Thanh tiến trình | C26: 1. Tại màn hình Survey 2. Kiểm tra hiển thị | D26: 2. Hiển thị hiệu ứng màu xanh trên thanh tiến trình tương ứng với trang đang mở | E26: P | H26: P | Q26: P
A27: =IF(AND(D27="",D27=""),"",$D$3&"_"&ROW()-11-COUNTBLANK($D$12:D27)) | B27: Kiểm tra hiển thị khi chuyển sang Step tiếp theo | C27: 1. Tại màn hình Survey 2. Kiểm tra hiển thị | D27: 2. Chuyển từ màu xám thành màu xanh đối với step mới, step cũ chuyển lại về màu xám. Hiệu ứng chuyển mượt mà | E27: P | H27: P | Q27: P
A28: =IF(AND(D28="",D28=""),"",$D$3&"_"&ROW()-11-COUNTBLANK($D$12:D28)) | B28: Kiểm tra hiển thị số trang | C28: 1. Tại màn hình Survey 2. Kiểm tra hiển thị | D28: 2. Số trang hiển thị khớp với vị trí step hiện tại đang ở | E28: P | H28: P | Q28: P
A29: =IF(AND(D29="",D29=""),"",$D$3&"_"&ROW()-11-COUNTBLANK($D$12:D29)) | B29: Kiểm tra hiển thị số trang khi chuyển step | C29: 1. Tại màn hình Survey 2. Kiểm tra hiển thị | D29: 2. Số trang tăng/giảm ứng với vị trí step hiện tại đang ở | E29: P | H29: P | Q29: P
A30: =IF(AND(D30="",D30=""),"",$D$3&"_"&ROW()-11-COUNTBLANK($D$12:D30)) | B30: Kiểm tra Label tiêu đề | C30: 1. Tại màn hình Survey 2. Kiểm tra hiển thị | D30: 2. Hiển thị text "Thông tin về bạn" | E30: P | H30: P | Q30: P
A31: =IF(AND(D31="",D31=""),"",$D$3&"_"&ROW()-11-COUNTBLANK($D$12:D31)) | B31: Kiểm tra hiển thị textbox | C31: 1. Tại màn hình Survey 2. Kiểm tra hiển thị | D31: 2. Các textbox hiển thị kích thước, màu sắc, vị trí như figma. Các placeholder text hiển thị chính xác | E31: P | H31: P | Q31: P
A32: =IF(AND(D32="",D32=""),"",$D$3&"_"&ROW()-11-COUNTBLANK($D$12:D32)) | B32: Kiểm tra hiển thị button Xác nhận | C32: 1. Tại màn hình Survey 2. Kiểm tra hiển thị | D32: 2. Hiển thị màu sắc, kích thước, vị trí như Figma | E32: P | H32: P | Q32: P
A33: =IF(AND(D33="",D33=""),"",$D$3&"_"&ROW()-11-COUNTBLANK($D$12:D33)) | B33: Kiểm tra hiển thị button Bỏ qua | C33: 1. Tại màn hình Survey 2. Kiểm tra hiển thị | D33: 2. Hiển thị màu sắc, kích thước, vị trí như Figma | E33: P | H33: P | Q33: P
A34: =IF(AND(D34="",D34=""),"",$D$3&"_"&ROW()-11-COUNTBLANK($D$12:D34)) | B34: Kiểm tra hiển thị progress | C34: 1. Tại màn hình survey 2. Điền thông tin và ấn xác nhận 3. Kiểm tra hiển thị | D34: 3. Hiển thị số số trang khớp với step: vd: Step 1 hiển thị 1/3 - Thanh tiến trình đổi màu đúng trạng thái | E34: P | H34: P | Q34: P
A35: =IF(AND(D35="",D35=""),"",$D$3&"_"&ROW()-11-COUNTBLANK($D$12:D35)) | B35: Validate
A36: =IF(AND(D36="",D36=""),"",$D$3&"_"&ROW()-11-COUNTBLANK($D$12:D36)) | B36: Validate trường Họ và tên
A37: =IF(AND(D37="",D37=""),"",$D$3&"_"&ROW()-11-COUNTBLANK($D$12:D37)) | B37: Kiểm tra trường bắt buộc | C37: 1. Để trống trường họ và tên 2. Click Xác nhận | D37: 2. Hiển thị thông báo lỗi "Không được để trống" | E37: P | H37: P | Q37: P
A38: =IF(AND(D38="",D38=""),"",$D$3&"_"&ROW()-11-COUNTBLANK($D$12:D38)) | B38: Kiểm tra placeholder | C38: 1. Quan sát textbox khi chưa nhập 2. Hover/click vào textbox | D38: 2. placeholder hiển thị là 'Họ và tên' | E38: P | H38: P | Q38: P
A39: =IF(AND(D39="",D39=""),"",$D$3&"_"&ROW()-11-COUNTBLANK($D$12:D39)) | B39: Kiểm tra trạng thái mặc định | C39: 1. Tại màn hình Thông tin về bạn | D39: 1. Enable | E39: P | H39: P | Q39: P
A40: =IF(AND(D40="",D40=""),"",$D$3&"_"&ROW()-11-COUNTBLANK($D$12:D40)) | B40: Kiểm tra nhập họ và tên hợp lệ | C40: 1. Tại màn hình Thông tin về bạn 2. Nhập giá trị họ và tên hợp lệ vào textbox | D40: 2. Ghi nhận giá trị đã nhập | E40: P | H40: P | Q40: P
A41: =IF(AND(D41="",D41=""),"",$D$3&"_"&ROW()-11-COUNTBLANK($D$12:D41)) | B41: Kiểm tra nhập text có chứa chữ thường | C41: 1. Click textbox 2. Nhập chữ thường 'abc' | D41: 2. Cho phép nhập - Hiển thị giá trị đã nhập | E41: P | H41: P | Q41: P
...

Sheet Home
C1: KỊCH BẢN KIỂM THỬ *
C2: Tên màn hình/Tên chức năng | D2: Màn hình home
C3: Mã trường hợp kiểm thử | D3: WBS-4
C4: Số trường hợp kiểm thử đạt (P) | D4: =COUNTIF($Q$15:$Q$1025,"P")
C5: Số trường hợp kiểm thử không đạt (F) | D5: =COUNTIF($Q$12:$Q$1025,"F")
C6: Số trường hợp kiểm thử đang xem xét (PE) | D6: =COUNTIF($Q$12:$Q$1025,"PE")
C7: Số trường hợp kiểm thử chưa thực hiện | D7: =D8-D4-D5-D6
C8: Tổng số trường hợp kiểm thử | D8: =COUNTA($D$15:$D$917)
A10: Mã test case | B10: Mục đích kiểm thử | C10: Các bước thực hiện | D10: Kết quả mong muốn | E10: Android | H10: IOS | K10: <Tên trình duyệt 3> | N10: <Tên trình duyệt 4> | Q10: Kết quả hiện tại | R10: Mã lỗi | S10: Ghi chú | T10: Ngày test | U10: Người test
E11: Lần 1 | F11: Lần 2 | G11: Lần 3 | H11: Lần 1 | I11: Lần 2 | J11: Lần 3 | K11: Lần 1 | L11: Lần 2 | M11: Lần 3 | N11: Lần 1 | O11: Lần 2 | P11: Lần 3
A12: =IF(AND(D12="",D12=""),"",$D$3&"_"&ROW()-11-COUNTBLANK($D$12:D12)) | B12: P
A13: =IF(AND(D13="",D13=""),"",$D$3&"_"&ROW()-11-COUNTBLANK($D$12:D13)) | B13: Tiền điều kiện | C13: • Người dùng đã cài đặt ứng dụng LaoOne. • Thiết bị có kết nối Internet.
A14: =IF(AND(D14="",D14=""),"",$D$3&"_"&ROW()-11-COUNTBLANK($D$12:D14)) | B14: Giao diện chung
A15: =IF(AND(D15="",D15=""),"",$D$3&"_"&ROW()-11-COUNTBLANK($D$12:D15)) | B15: Kiểm tra giao diện màn hình Home | C15: 1. Tại màn hình Home 2. Kiểm tra hiển thị | D15: 1. Hiển thị màn hình: - Tài khoản người dùng - Icon Tìm kiếm, App của tôi - Banner quảng bá - Tab chính phủ số/ doanh nghiệp số - Text "Bộ giải pháp phổ biến", mũi tên xem thêm - Grid Danh sách giải pháp phổ biến - Item giải pháp/ item xem thêm - Text "Bộ giải pháp theo lĩnh vực", mũi tên xem thêm - Card các lĩnh vực - Text Chuyển động số, mũi tên xem thêm - Danh sách tin tức - Danh sách các miniapp - Bottom navigation bar | E15: P | H15: P | Q15: P
A16: =IF(AND(D16="",D16=""),"",$D$3&"_"&ROW()-11-COUNTBLANK($D$12:D16)) | C16: 3. Kiểm tra tổng thể giao diện: font chữ, chính tả, title... | D16: 2. Font chữ, cỡ chữ, màu sắc chữ, độ rộng cột, độ rộng hàng, màu sắc background, icon, vị trí icon, title, khoảng cách giữa các đối tượng hiển thị,... đúng với thiết kế | E16: P | H16: P | Q16: P
A17: =IF(AND(D17="",D17=""),"",$D$3&"_"&ROW()-11-COUNTBLANK($D$12:D17)) | C17: 4. Kiểm tra responsive | D17: 3. Thay đổi độ phân giải chuẩn khác nhau, màn hình và các control tuân thủ đúng nguyên tắc responsive, không bị vỡ cấu trúc | E17: P | H17: P | Q17: P
A18: =IF(AND(D18="",D18=""),"",$D$3&"_"&ROW()-11-COUNTBLANK($D$12:D18)) | C18: Hình ảnh | E18: P | H18: P | Q18: P
A19: =IF(AND(D19="",D19=""),"",$D$3&"_"&ROW()-11-COUNTBLANK($D$12:D19)) | B19: Kiểm tra hiển thị khi xoay màn hình theo chiều dọc/chiều ngang | C19: 1. Tại màn hình Login 2. Kiểm tra hiển thị 3. Bật tính năng xoay màn hình của thiết bị 4. Xoay ngang/dọc màn hình | D19: 1. Không di chuyển, giữ nguyên vùng màn hình | E19: P | H19: P | Q19: P
A20: =IF(AND(D20="",D20=""),"",$D$3&"_"&ROW()-11-COUNTBLANK($D$12:D20)) | B20: Kiểm tra giao diện khi scroll lên/xuống | C20: 1. Tại màn hình Login 2. Srcoll lên/xuống | D20: 1. Màn hình được scroll mượt mà, không bị giật lag | E20: P | H20: P | Q20: P
A21: =IF(AND(D21="",D21=""),"",$D$3&"_"&ROW()-11-COUNTBLANK($D$12:D21)) | B21: Kiểm tra giao diện ở trường hợp ngắt kết nối mạng | C21: 1. Ngắt kết nối mạng 2. Kết nối lại mạng | D21: 1. Hiển thị giao diện ngoại tuyến, thông báo "Không có kết nối mạng" 2. Hiển thị giao diện mặc định | E21: P | H21: P | Q21: P
A22: =IF(AND(D22="",D22=""),"",$D$3&"_"&ROW()-11-COUNTBLANK($D$12:D22)) | B22: Giao diện của HEADER | H22: P
A23: =IF(AND(D23="",D23=""),"",$D$3&"_"&ROW()-11-COUNTBLANK($D$12:D23)) | B23: Kiểm tra hiển thị header | C23: 1. Tại màn hình Home 2. Kiểm tra hiển thị | D23: Các thành phần: - Thông tin tài khoản/ nút đăng nhập (chưa login) - Nút tìm kiếm - App của tôi | E23: P | H23: P | Q23: P
A24: =IF(AND(D24="",D24=""),"",$D$3&"_"&ROW()-11-COUNTBLANK($D$12:D24)) | B24: Kiểm tra hiển thị avatar người dùng | C24: Pre: Đã đăng nhập thành công vào hệ thống 1. Tại màn hình Home 2. Kiểm tra hiển thị | D24: Hiển thị avatar mặc định khi người dùng chưa thay đổi avatar Hiển thị hình ảnh người dùng tải lên khi người dùng thay đổi avatar | E24: P | H24: P | Q24: P
A25: =IF(AND(D25="",D25=""),"",$D$3&"_"&ROW()-11-COUNTBLANK($D$12:D25)) | C25: Pre: Chưa đăng nhập vào hệ thống 1. Tại màn hình Home 2. Kiểm tra hiển thị | D25: Hiển thị avatar giống figma | E25: P | H25: P | Q25: P
A26: =IF(AND(D26="",D26=""),"",$D$3&"_"&ROW()-11-COUNTBLANK($D$12:D26)) | B26: Kiểm tra hiển thị text | C26: Pre: Đã đăng nhập thành công vào hệ thống 1. Tại màn hình Home 2. Kiểm tra hiển thị | D26: Hiển thị text "Welcome to LaoOne!" + tên user | E26: P | H26: P | Q26: P
A27: =IF(AND(D27="",D27=""),"",$D$3&"_"&ROW()-11-COUNTBLANK($D$12:D27)) | C27: Pre: Chưa đăng nhập vào hệ thống 1. Tại màn hình Home 2. Kiểm tra hiển thị | D27: Hiển thị text "Đăng nhập" | E27: P | H27: P | Q27: P
A28: =IF(AND(D28="",D28=""),"",$D$3&"_"&ROW()-11-COUNTBLANK($D$12:D28)) | B28: Kiểm tra ấn button Đăng nhập | C28: Pre: Chưa đăng nhập vào hệ thống 1. Tại màn hình Home 2. Ấn vào button Đăng nhập | D28: Điều hướng sang màn hình Đăng nhập | E28: P | H28: P | Q28: P
A29: =IF(AND(D29="",D29=""),"",$D$3&"_"&ROW()-11-COUNTBLANK($D$12:D29)) | B29: Kiểm tra ấn button tên user | C29: Pre: Đã đăng nhập thành công vào hệ thống 1. Tại màn hình Home 2. Ấn vào user | D29: Điều hướng sang màn hình Tài khoản | E29: P | H29: P | Q29: P
A30: =IF(AND(D30="",D30=""),"",$D$3&"_"&ROW()-11-COUNTBLANK($D$12:D30)) | B30: Kiểm tra icon tìm kiếm | C30: 1. Tại màn hình Home 2. Kiểm tra hiển thị | D30: Hiển thị đúng màu sắc, kích thước, vị trí như figma | E30: P | H30: P | Q30: P
A31: =IF(AND(D31="",D31=""),"",$D$3&"_"&ROW()-11-COUNTBLANK($D$12:D31)) | B31: Kiểm tra click icon tìm kiếm | C31: 1. Tại màn hình Home 2. Click icon 3. Kiểm tra hiển thị | D31: Điều hướng sang màn hình tìm kiếm | E31: P | H31: P | Q31: P
A32: =IF(AND(D32="",D32=""),"",$D$3&"_"&ROW()-11-COUNTBLANK($D$12:D32)) | B32: Kiểm tra icon App của tôi | C32: 1. Tại màn hình Home 2. Kiểm tra hiển thị | D32: Hiển thị đúng màu sắc, kích thước, vị trí như figma | E32: P | H32: P | Q32: P
A33: =IF(AND(D33="",D33=""),"",$D$3&"_"&ROW()-11-COUNTBLANK($D$12:D33)) | B33: Kiểm tra click icon App của tôi | C33: 1. Tại màn hình Home 2. Click icon 3. Kiểm tra hiển thị | D33: Điều hướng tới màn hình app của tôi | E33: P | H33: P | Q33: P
A34: =IF(AND(D34="",D34=""),"",$D$3&"_"&ROW()-11-COUNTBLANK($D$12:D34)) | B34: Giao diện Tìm kiếm
A35: =IF(AND(D35="",D35=""),"",$D$3&"_"&ROW()-11-COUNTBLANK($D$12:D35)) | B35: Kiểm tra giao diện mặc định màn Tìm kiếm | C35: 1. Tại màn hình Home 2. Nhấn icon Tìm kiếm 3. Kiểm tra giao diện | D35: 3. Hiển thị giao diện màn tìm kiếm: - Button Quay lại hình mũi tên - TextboxTìm kiếm - Text Bộ giải pháp đề xuất + Hiển thị 3 Bộ giải pháp đề xuất - Text Mini Apps + Hiển thị 3 miniapp - Text Giải pháp đề xuất + Hiển thị 3 giải pháp đề xuất | E35: P | H35: P | Q35: P
A36: =IF(AND(D36="",D36=""),"",$D$3&"_"&ROW()-11-COUNTBLANK($D$12:D36)) | B36: Kiểm tra scroll | C36: 1. Tại màn hình Tìm kiếm 2. Thực hiện scroll | D36: 2. Scroll lên/xuống mượt mà, không giật lag | E36: P | H36: P | Q36: P
B37: Kiểm tra hiển thị Tìm kiếm gần đây | C37: 1. Tại màn hình tìm kiếm 2. Thực hiện tìm kiếm >>Nhấn vào kết quả 3. Quay lại màn tìm kiếm >>Kiểm tra hiển thị | D37: 3. Màn hình hiển thị thêm 1 phần Tìm kiếm gần đây | E37: P | H37: P
A38: =IF(AND(D38="",D38=""),"",$D$3&"_"&ROW()-11-COUNTBLANK($D$12:D38)) | B38: Validate Tìm kiếm
A39: =IF(AND(D39="",D39=""),"",$D$3&"_"&ROW()-11-COUNTBLANK($D$12:D39)) | B39: Kiểm tra khi nhập từ khóa có trong hệ thống | C39: 1. Tại màn hình tìm kiếm 2. Nhập từ khóa có trong hệ thống 3. Kiểm tra kết quả | D39: 3. Trả về các kết quả khớp với từ khóa
A40: =IF(AND(D40="",D40=""),"",$D$3&"_"&ROW()-11-COUNTBLANK($D$12:D40)) | B40: Kiểm tra khi nhập từ khóa không có trong hệ thống | C40: 1. Tại màn hình tìm kiếm 2. Nhập từ khóa không có trong hệ thống 3. Kiểm tra kết quả | D40: 3. Hiển thị thông báo "Không tìm thấy kết quả"
A41: =IF(AND(D41="",D41=""),"",$D$3&"_"&ROW()-11-COUNTBLANK($D$12:D41)) | B41: Kiểm tra tìm kiếm theo tên đầy đủ | C41: 1. Tại màn hình tìm kiếm 2. Nhập tên đầy đủ 3. Kiểm tra kết quả | D41: 3. Hiển thị đầy đủ kết quả trả về
...

Sheet 5. Màn hình quan tâm
C1: KỊCH BẢN KIỂM THỬ *
C2: Tên màn hình/Tên chức năng | D2: Màn hình Quan tâm
C3: Mã trường hợp kiểm thử | D3: WBS-5
C4: Số trường hợp kiểm thử đạt (P) | D4: =COUNTIF($Q$12:$Q$191,"P")
C5: Số trường hợp kiểm thử không đạt (F) | D5: =COUNTIF($Q$12:$Q$191,"F")
C6: Số trường hợp kiểm thử đang xem xét (PE) | D6: =COUNTIF($Q$12:$Q$191,"PE")
C7: Số trường hợp kiểm thử chưa thực hiện | D7: =D8-D4-D5-D6
C8: Tổng số trường hợp kiểm thử | D8: =COUNTA($D$12:$D$191)
A10: Mã trường hợp kiểm thử | B10: Mục đích kiểm thử | C10: Các bước thực hiện | D10: Kết quả mong muốn | E10: Android | H10: IOS | K10: <Tên trình duyệt 3> | N10: <Tên trình duyệt 4> | Q10: Kết quả hiện tại | R10: Mã lỗi | S10: Ghi chú
E11: Lần 1 | F11: Lần 2 | G11: Lần 3 | H11: Lần 1 | I11: Lần 2 | J11: Lần 3 | K11: Lần 1 | L11: Lần 2 | M11: Lần 3 | N11: Lần 1 | O11: Lần 2 | P11: Lần 3
A12: =IF(AND(D12="",D12=""),"",$D$3&"_"&ROW()-11-COUNTBLANK($D$12:D12)) | B12: WBS 5.6: Màn hình Quan tâm
A13: =IF(AND(D13="",D13=""),"",$D$3&"_"&ROW()-11-COUNTBLANK($D$12:D13)) | B13: Giao diện (Phần này viết các trường hợp kiểm thử cho giao diên chung và các giao diện cho các control)
A14: =IF(AND(D16="",D16=""),"",$D$3&"_"&ROW()-11-COUNTBLANK($D$12:D16)) | B14: Kiểm tra giao diện mặc định | C14: pre: Chưa đăng nhập 1. Mở app 2. Từ màn chi tiết giải pháp → nhấn “Quan tâm” 3. Điều hướng sang màn “Đăng ký quan tâm” | D14: 2. Giao diện hiển thị: - Tiêu đề màn hình: “Quan tâm” - Input “Họ và tên” - Input “Số điện thoại” - Input “Đơn vị” - Input “Địa chỉ” - Textarea “Nội dung yêu cầu” - Button “Gửi thông tin” (Disabled) - Bottom navigation: Trang chủ / Quan tâm / Logo / Thông báo / Tài khoản | E14: P | H14: P | Q14: P
A15: =IF(AND(D17="",D17=""),"",$D$3&"_"&ROW()-11-COUNTBLANK($D$12:D17)) | C15: Hình ảnh | E15: P | H15: P | Q15: P
A16: =IF(AND(D16="",D16=""),"",$D$3&"_"&ROW()-11-COUNTBLANK($D$12:D16)) | C16: Pre: Đã đăng nhập 1. Truy cập màn hình Quan tâm 2. Quan sát giao diện | D16: 2. Giao diện hiển thị: - Tiêu đề màn hình: “Quan tâm” - Input “Họ và tên” - Input “Số điện thoại” - Input “Đơn vị” - Input “Địa chỉ” - Textarea “Nội dung yêu cầu” - Button “Gửi thông tin” (Disabled) - Bottom navigation: Trang chủ / Quan tâm / Logo / Thông báo / Tài khoản | E16: P | H16: P | Q16: P
A17: =IF(AND(D17="",D17=""),"",$D$3&"_"&ROW()-11-COUNTBLANK($D$12:D17)) | C17: Hình ảnh | E17: P | H17: P | Q17: P
A18: =IF(AND(D18="",D18=""),"",$D$3&"_"&ROW()-11-COUNTBLANK($D$12:D18)) | B18: Kiểm tra trạng thái mặc định của các field | C18: Pre: Thiết bị có kết nối Internet 1. Truy cập màn hình Quan tâm 2. Quan sát các field input | D18: 2. Các field: - Rỗng - Không hiển thị lỗi - Placeholder hiển thị đúng theo thiết kế | E18: P | H18: P | Q18: P
A19: =IF(AND(D19="",D19=""),"",$D$3&"_"&ROW()-11-COUNTBLANK($D$12:D19)) | B19: Kiểm tra button “Gửi thông tin” trạng thái ban đầu | C19: Pre: Truy cập màn Quan tâm 1. Quan sát button Gửi thông tin | D19: 1. Button ở trạng thái Disabled khi chưa nhập dữ liệu | E19: P | H19: P | Q19: P
A20: =IF(AND(D20="",D20=""),"",$D$3&"_"&ROW()-11-COUNTBLANK($D$12:D20)) | B20: Kiểm tra tổng thể giao diện màn hình | C20: 1. Kiểm tra chính tả. bố cục, màu chữ, font chữ 2. Kiểm tra textbox, button, lỗi chính tả | D20: 1. Các label, textbox, combo cùng font chữ, cỡ chữ, căn lề trái, có độ dài, rộng và khoảng cách bằng nhau, không xô lệch 2. Không có lỗi chính tả, cấu trúc câu, ngữ pháp trên màn hình, form được bố trí hợp lý và dễ sử dụng. | E20: P | H20: P | Q20: P
A21: =IF(AND(D21="",D21=""),"",$D$3&"_"&ROW()-11-COUNTBLANK($D$12:D21)) | B21: Kiểm tra giao diện khi scroll lên/xuống | C21: 1. Srcoll lên/xuống | D21: 1. Màn hình được scroll mượt mà, không bị giật lag | E21: P | H21: P | Q21: P
A22: =IF(AND(D22="",D22=""),"",$D$3&"_"&ROW()-11-COUNTBLANK($D$12:D22)) | B22: Kiểm tra chức năng xoay màn hình theo chiều dọc/chiều ngang | C22: 1. Bật tính năng xoay màn hình của thiết bị 2. Xoay ngang/dọc màn hình | D22: 2. Không di chuyển, giữ nguyên vùng màn hình | E22: P | H22: P | Q22: P
A23: =IF(AND(D23="",D23=""),"",$D$3&"_"&ROW()-11-COUNTBLANK($D$12:D23)) | B23: Validate trường họ và tên
A24: =IF(AND(D24="",D24=""),"",$D$3&"_"&ROW()-11-COUNTBLANK($D$12:D24)) | B24: Kiểm tra trường bắt buộc | C24: 1. Để tróng trường họ và tên 2. Click Gửi thông tin | D24: 2. Hiển thị dấu *, bắt buộc nhập - Placeholder: "Họ và tên" | E24: P | H24: P | Q24: P
A25: =IF(AND(D25="",D25=""),"",$D$3&"_"&ROW()-11-COUNTBLANK($D$12:D25)) | B25: Kiểm tra placeholder | C25: 1. Quan sát textbox khi chưa nhập 2. Hover/click vào textbox | D25: 2. placeholder hiển thị là 'Họ và tên' | E25: P | H25: P | Q25: P
A26: =IF(AND(D26="",D26=""),"",$D$3&"_"&ROW()-11-COUNTBLANK($D$12:D26)) | B26: Kiểm tra trạng thái mặc định | C26: 1. Tại màn hình Thông tin về bạn | D26: 1. Enable | E26: P | H26: P | Q26: P
A27: =IF(AND(D27="",D27=""),"",$D$3&"_"&ROW()-11-COUNTBLANK($D$12:D27)) | B27: Kiểm tra nhập họ và tên hợp lệ | C27: 1. Tại màn hình Thông tin về bạn 2. Nhập giá trị họ và tên hợp lệ vào textbox | D27: 2. Ghi nhận giá trị đã nhập | E27: P | H27: P | Q27: P
A28: =IF(AND(D28="",D28=""),"",$D$3&"_"&ROW()-11-COUNTBLANK($D$12:D28)) | B28: Kiểm tra nhập all space | C28: 1. Click textbox 2. Nhập khoảng trắng " " | D28: 2. Chặn không cho phép nhập all space | E28: P | H28: P | Q28: P
A29: =IF(AND(D29="",D29=""),"",$D$3&"_"&ROW()-11-COUNTBLANK($D$12:D29)) | B29: Kiểm tra nhập text có khoảng trắng đầu cuối | C29: 1. Click textbox 2. Nhập kí tự có khoảng trắng đầu cuối ' abc ' | D29: 2. Cho phép nhập Không báo lỗi | E29: P | H29: P | Q29: P
A30: =IF(AND(D30="",D30=""),"",$D$3&"_"&ROW()-11-COUNTBLANK($D$12:D30)) | B30: Kiểm tra nhập text có chứa chữ thường | C30: 1. Click textbox 2. Nhập chữ thường 'abc' | D30: 2. Cho phép nhập - Hiển thị giá trị đã nhập | E30: P | H30: P | Q30: P
A31: =IF(AND(D31="",D31=""),"",$D$3&"_"&ROW()-11-COUNTBLANK($D$12:D31)) | B31: Kiêm tra nhâp text có chứa chữ hoa | C31: 1. Click textbox 2. Nhập chữ hoa 'ABC' | D31: 2. Cho phép nhập - Hiển thị giá trị đã nhập | E31: P | H31: P | Q31: P
A32: =IF(AND(D32="",D32=""),"",$D$3&"_"&ROW()-11-COUNTBLANK($D$12:D32)) | B32: Kiểm tra nhập tiếng Việt có dấu | C32: 1. Click textbox 2. Nhập dữ liệu: ' xin chào' | D32: 2. Cho phép nhập - Hiển thị giá trị đã nhập | E32: P | H32: P | Q32: P
A33: =IF(AND(D33="",D33=""),"",$D$3&"_"&ROW()-11-COUNTBLANK($D$12:D33)) | B33: Kiểm tra nhập ký tự đặc biệt | C33: 1. Click textbox 2. Nhập ký tự đặc biệt '@#' | D33: 2. Chặn không cho phép nhập | E33: P | H33: P | Q33: P
A34: =IF(AND(D34="",D34=""),"",$D$3&"_"&ROW()-11-COUNTBLANK($D$12:D34)) | B34: Kiểm tra nhập số | C34: 1. Click textbox 2. Nhập ký tự số '123' | D34: 2. Chặn không cho phép nhập | E34: P | H34: P | Q34: P
A35: =IF(AND(D35="",D35=""),"",$D$3&"_"&ROW()-11-COUNTBLANK($D$12:D35)) | B35: Kiểm tra trường hợp nhập giá trị ký tự là chữ vào textbox | C35: 1. Tại màn hình Thông tin về bạn 2. Người dùng nhập giá trị có ký tự là chữ 3. Kiểm tra hiển thị | D35: 1. Ghi nhận giá trị đã nhập | E35: P | H35: P | Q35: P
... A40: =IF(AND(D40="",D40=""),"",$D$3&"_"&ROW()-11-COUNTBLANK($D$12:D40)) | B40: Kiểm tra xóa giá trị đã nhập tại textbox | C40: 1. Tại màn hình Thông tin về bạn 2. Xóa dữ liệu họ và tên hợp lệ | D40: 1. Xóa thành công | E40: P | H40: P | Q40: P
A41: =IF(AND(D41="",D41=""),"",$D$3&"_"&ROW()-11-COUNTBLANK($D$12:D41)) | B41: Validate trường số điện thoại
A42: =IF(AND(D42="",D42=""),"",$D$3&"_"&ROW()-11-COUNTBLANK($D$12:D42)) | B42: Kiểm tra trường bắt buộc | C42: 1. Để tróng trường số điện thoại 2. Click Xác nhận | D42: 2. Hiển thị dấu *, bắt buộc nhập | E42: P | H42: P | Q42: P
A43: =IF(AND(D43="",D43=""),"",$D$3&"_"&ROW()-11-COUNTBLANK($D$12:D43)) | B43: Kiểm tra placeholder | C43: 1. Quan sát textbox khi chưa nhập 2. Hover/click vào textbox | D43: 2. placeholder hiển thị là 'Số điện thoại' | E43: P | H43: P | Q43: P
A44: =IF(AND(D44="",D44=""),"",$D$3&"_"&ROW()-11-COUNTBLANK($D$12:D44)) | B44: Kiểm tra trạng thái mặc định | C44: 1. Tại màn hình Thông tin về bạn | D44: 1. Enable | E44: P | H44: P | Q44: P
A45: =IF(AND(D45="",D45=""),"",$D$3&"_"&ROW()-11-COUNTBLANK($D$12:D45)) | B45: Kiểm tra nhập số điện thoại hợp lệ | C45: 1. Tại màn hình Thông tin về bạn 2. Nhập sđt hợp lệ vào trường | D45: 1. Ghi nhận giá trị đã nhập | E45: P | H45: P | Q45: P
...

Sheet 6.AboutUnitel
C1: KỊCH BẢN KIỂM THỬ *
C2: Tên màn hình/Tên chức năng | D2: About/Unitel
C3: Mã trường hợp kiểm thử | D3: WBS-6
C4: Số trường hợp kiểm thử đạt (P) | D4: =COUNTIF($Q$12:$Q$115,"P")
C5: Số trường hợp kiểm thử không đạt (F) | D5: =COUNTIF($Q$12:$Q$115,"F")
C6: Số trường hợp kiểm thử đang xem xét (PE) | D6: =COUNTIF($Q$12:$Q$115,"PE")
C7: Số trường hợp kiểm thử chưa thực hiện | D7: =D8-D4-D5-D6
C8: Tổng số trường hợp kiểm thử | D8: =COUNTA($D$12:$D$115)
A10: Mã trường hợp kiểm thử | B10: Mục đích kiểm thử | C10: Các bước thực hiện | D10: Kết quả mong muốn | E10: Android | H10: IOS | K10: <Tên trình duyệt 3> | N10: <Tên trình duyệt 4> | Q10: Kết quả hiện tại | R10: Mã lỗi | S10: Ghi chú
E11: Lần 1 | F11: Lần 2 | G11: Lần 3 | H11: Lần 1 | I11: Lần 2 | J11: Lần 3 | K11: Lần 1 | L11: Lần 2 | M11: Lần 3 | N11: Lần 1 | O11: Lần 2 | P11: Lần 3
A12: =IF(AND(D12="",D12=""),"",$D$3&"_"&ROW()-11-COUNTBLANK($D$12:D12)) | B12: WBS 6.24: Màn hình About/Unitel
A13: =IF(AND(D13="",D13=""),"",$D$3&"_"&ROW()-11-COUNTBLANK($D$12:D13)) | B13: Giao diện (Phần này viết các trường hợp kiểm thử cho giao diên chung và các giao diện cho các control)
B14: Giao diện chung
A15: =IF(AND(D15="",D15=""),"",$D$3&"_"&ROW()-11-COUNTBLANK($D$12:D15)) | B15: Kiểm tra giao diện mặc định | C15: Pre: Hệ thống hoạt động bình thường 1. Mở app 2. Truy cập màn About Unitel | D15: 2. Hiển thị đúng nội dung màn About Unitel gồm các thành phần: - Header: + Header (logo + navigation) + Banner / Video: - Thông tin chung: + Logo Unitel (image) + Tiêu đề section: “Giới thiệu” + Nội dung mô tả (Rich text từ CMS) + Button Expand/Collapse (Xem thêm) - Block thông tin: + Block Tầm nhìn (Card + icon + nội dung) + Block Sứ mệnh (Card + icon + nội dung) - Năng lực hạ tầng: + Tiêu đề section: “Năng lực hạ tầng” + Infographic preview (circular layout từ CMS) + Button “Xem chi tiết” - Đối tác tiêu biểu: + Tiêu đề section: “Đối tác tiêu biểu” + Danh sách đối tác (Horizontal list) + Logo đối tác (image từ CMS) - Giải thưởng và thành tựu: + Tiêu đề section: “Giải thưởng và thành tựu” + Danh sách giải thưởng (list từ CMS) + Icon/Ảnh minh họa + Nội dung mô tả Bottom navigation: Trang chủ / Quan tâm / Logo / Thông báo / Tài khoản | E15: P | H15: P | Q15: P
A16: =IF(AND(D16="",D16=""),"",$D$3&"_"&ROW()-11-COUNTBLANK($D$12:D16)) | C16: Hình ảnh | E16: P | H16: P | Q16: P
A17: =IF(AND(D17="",D17=""),"",$D$3&"_"&ROW()-11-COUNTBLANK($D$12:D17)) | B17: Kiểm tra tổng thể giao diện màn hình | C17: 1. Kiểm tra chính tả. bố cục, màu chữ, font chữ 2. Kiểm tra textbox, button, lỗi chính tả | D17: 1. Các label, textbox, combo cùng font chữ, cỡ chữ, căn lề trái, có độ dài, rộng và khoảng cách bằng nhau, không xô lệch 2. Không có lỗi chính tả, cấu trúc câu, ngữ pháp trên màn hình, form được bố trí hợp lý và dễ sử dụng. | E17: P | H17: P | Q17: P
A18: =IF(AND(D18="",D18=""),"",$D$3&"_"&ROW()-11-COUNTBLANK($D$12:D18)) | B18: Kiểm tra hiển thị banner/video | C18: 1. Quan sát khu vực banner | D18: 1. - Hiển thị đúng hình/video từ CMS- Không bị méo hoặc vỡ | E18: P | H18: P | Q18: P
A19: =IF(AND(D19="",D19=""),"",$D$3&"_"&ROW()-11-COUNTBLANK($D$12:D19)) | B19: Kiểm tra hiển thị section nội dung | C19: 1. Scroll màn hình | D19: 1. - Hiển thị đủ các section- Khoảng cách hợp lý | E19: P | H19: P | Q19: P
A20: =IF(AND(D20="",D20=""),"",$D$3&"_"&ROW()-11-COUNTBLANK($D$12:D20)) | B20: Kiểm tra hiển thị section Hạ tầng | C20: 1. Scroll tới Hạ tầng | D20: 1. - Hiển thị infographic/icon- Có tiêu đề + mô tả | E20: P | H20: P | Q20: P
A21: =IF(AND(D21="",D21=""),"",$D$3&"_"&ROW()-11-COUNTBLANK($D$12:D21)) | B21: Kiểm tra hiển thị section Đối tác | C21: 1. Scroll tới Đối tác | D21: 1. - Hiển thị danh sách logo- Logo rõ ràng | E21: P | H21: P | Q21: P
A22: =IF(AND(D22="",D22=""),"",$D$3&"_"&ROW()-11-COUNTBLANK($D$12:D22)) | B22: Kiểm tra hiển thị section Thành tựu | C22: 1. Scroll tới Thành tựu | D22: 1. - Hiển thị danh sách thành tựu- Có text + icon | E22: P | H22: P | Q22: P
A23: =IF(AND(D23="",D23=""),"",$D$3&"_"&ROW()-11-COUNTBLANK($D$12:D23)) | B23: Kiểm tra chuyển Light → Dark | C23: 1. Đổi theme | D23: 1. UI cập nhật đúng, không reload | E23: P | H23: P | Q23: P
A24: =IF(AND(D24="",D24=""),"",$D$3&"_"&ROW()-11-COUNTBLANK($D$12:D24)) | B24: Kiểm tra hiển thị Light mode | C24: 1. Set Light mode | D24: 1. UI nền sáng, text rõ | E24: P | H24: P | Q24: P
A25: =IF(AND(D25="",D25=""),"",$D$3&"_"&ROW()-11-COUNTBLANK($D$12:D25)) | B25: Kiểm tra hiển thị Dark mode | C25: 1. Set Dark mode | D25: 1. UI nền tối, text rõ | E25: P | H25: P | Q25: P
A26: =IF(AND(D26="",D26=""),"",$D$3&"_"&ROW()-11-COUNTBLANK($D$12:D26)) | B26: Kiểm tra scroll màn hình | C26: 1. Scroll lên/xuống | D26: 1. Scroll mượt, không lag | E26: P | H26: P | Q26: P
A27: =IF(AND(D27="",D27=""),"",$D$3&"_"&ROW()-11-COUNTBLANK($D$12:D27)) | B27: Set font chữ lớn (Accessibility) | C27: 1. Tăng font size 2. Mở màn About | D27: 2. - Text hiển thị đầy đủ- Không vỡ layout | E27: P | H27: P | Q27: P
A28: =IF(AND(D28="",D28=""),"",$D$3&"_"&ROW()-11-COUNTBLANK($D$12:D28)) | B28: Set font chữ nhỏ | C28: 1. Giảm font size 2. Mở màn | D28: 2. UI hiển thị cân đối | E28: P | H28: P | Q28: P
... A35: =IF(AND(D35="",D35=""),"",$D$3&"_"&ROW()-11-COUNTBLANK($D$12:D35)) | B35: Test nhiều màn hình | C35: 1. Test device nhỏ/lớn | D35: 1. Không vỡ layout | E35: P | H35: P | Q35: P
A36: =IF(AND(D36="",D36=""),"",$D$3&"_"&ROW()-11-COUNTBLANK($D$12:D36)) | B36: WBS 6.25: Luồng hiển thị video
A37: =IF(AND(D37="",D37=""),"",$D$3&"_"&ROW()-11-COUNTBLANK($D$12:D37)) | B37: Giao diện (Phần này viết các trường hợp kiểm thử cho giao diên chung và các giao diện cho các control)
A38: =IF(AND(D38="",D38=""),"",$D$3&"_"&ROW()-11-COUNTBLANK($D$12:D38)) | B38: Giao diện chung
A39: =IF(AND(D39="",D39=""),"",$D$3&"_"&ROW()-11-COUNTBLANK($D$12:D39)) | B39: Kiểm tra hiển thị video mặc định | C39: Pre: CMS có cấu hình video/banner 1. Truy cập màn About us 2. Quan sát khu vực banner/video | D39: 2. Video/banner hiển thị: - Hiển thị đúng dữ liệu từ CMS - Không vỡ/méo hình - Đúng vị trí layout | E39: P | H39: P | Q39: P
A40: =IF(AND(D40="",D40=""),"",$D$3&"_"&ROW()-11-COUNTBLANK($D$12:D40)) | C40: Pre: CMS không có video 1. Truy cập màn About us 2. Quan sát khu vực banner/video | D40: 2. Khu vực video: - Không hiển thị video hoặc hiển thị ảnh thay thế - Không lỗi UI | E40: P | H40: P | Q40: P
A41: =IF(AND(D41="",D41=""),"",$D$3&"_"&ROW()-11-COUNTBLANK($D$12:D41)) | C41: Hình ảnh | E41: P | H41: P | Q41: P
A42: =IF(AND(D42="",D42=""),"",$D$3&"_"&ROW()-11-COUNTBLANK($D$12:D42)) | B42: Kiểm tra loading video | C42: Pre: Mạng chậm 1. Truy cập màn About 2. Quan sát video | D42: 2. Video hiển thị: - Có loading - Không treo màn hình | E42: P | H42: P | Q42: P
A43: =IF(AND(D43="",D43=""),"",$D$3&"_"&ROW()-11-COUNTBLANK($D$12:D43)) | B43: Kiểm tra API lỗi | C43: Pre: API trả lỗi 1. Truy cập màn About 2. Quan sát video | D43: 2. Video hiển thị: - Không crash - UI vẫn hiển thị bình thường | E43: P | H43: P | Q43: P
A44: =IF(AND(D44="",D44=""),"",$D$3&"_"&ROW()-11-COUNTBLANK($D$12:D44)) | B44: Kiểm tra hiển thị responsive | C44: Pre: Bình thường 1. Truy cập màn About 2. Test nhiều kích thước màn hình | D44: 2. Video hiển thị: - Đúng kích thước - Không vỡ layout | E44: P | H44: P | Q44: P
A45: =IF(AND(D45="",D45=""),"",$D$3&"_"&ROW()-11-COUNTBLANK($D$12:D45)) | B45: Chức năng (Phần này viết các trường hợp kiểm thử kiểm tra các ràng buộc trong cơ sở dữ liệu và cho các luồng nghiệp vụ trong tài liệu giải pháp, tích hợp với các chức năng khác) | Q45: =IF(OR(IF(G45="",IF(F45="",IF(E45="","",E45),F45),G45)="F",IF(J45="",IF(I45="",IF(H45="","",H45),I45),J45)="F",IF(M45="",IF(L45="",IF(K45="","",K45),L45),M45)="F",IF(P45="",IF(O45="",IF(N45="","",N45),O45),P45)="F")=TRUE,"F",IF(OR(IF(G45="",IF(F45="",IF(E45="","",E45),F45),G45)="PE",IF(J45="",IF(I45="",IF(H45="","",H45),I45),J45)="PE",IF(M45="",IF(L45="",IF(K45="","",K45),L45),M45)="PE",IF(P45="",IF(O45="",IF(N45="","",N45),O45),P45)="PE")=TRUE,"PE",IF(AND(IF(G45="",IF(F45="",IF(E45="","",E45),F45),G45)="",IF(J45="",IF(I45="",IF(H45="","",H45),I45),J45)="",IF(M45="",IF(L45="",IF(K45="","",K45),L45),M45)="",IF(P45="",IF(O45="",IF(N45="","",N45),O45),P45)="")=TRUE,"","P")))
A46: =IF(AND(D46="",D46=""),"",$D$3&"_"&ROW()-11-COUNTBLANK($D$12:D46)) | B46: Kiểm tra play video bằng nút Play | C46: 1. Truy cập màn hình 2. Nhấn nút Play | D46: 2. Video bắt đầu phát Thanh progress hoạt động Âm thanh | E46: P | H46: P | Q46: P
A47: =IF(AND(D47="",D47=""),"",$D$3&"_"&ROW()-11-COUNTBLANK($D$12:D47)) | B47: Kiểm tra auto play | C47: Pre: Video có auto play 1. Truy cập màn hình | D47: 1. Video tự động phát khi load xong | E47: P | H47: P | Q47: P
...

Sheet 7. Thông báo 
C1: KỊCH BẢN KIỂM THỬ *
C2: Tên màn hình/Tên chức năng | D2: Thông báo
C3: Mã trường hợp kiểm thử | D3: WBS-7
C4: Số trường hợp kiểm thử đạt (P) | D4: =COUNTIF($Q$12:$Q$146,"P")
C5: Số trường hợp kiểm thử không đạt (F) | D5: =COUNTIF($Q$12:$Q$146,"F")
C6: Số trường hợp kiểm thử đang xem xét (PE) | D6: =COUNTIF($Q$12:$Q$146,"PE")
C7: Số trường hợp kiểm thử chưa thực hiện | D7: =D8-D4-D5-D6
C8: Tổng số trường hợp kiểm thử | D8: =COUNTA($D$12:$D$146)
A10: Mã trường hợp kiểm thử | B10: Mục đích kiểm thử | C10: Các bước thực hiện | D10: Kết quả mong muốn | E10: Android | H10: IOS | K10: <Tên trình duyệt 3> | N10: <Tên trình duyệt 4> | Q10: Kết quả hiện tại | R10: Mã lỗi | S10: Ghi chú
E11: Lần 1 | F11: Lần 2 | G11: Lần 3 | H11: Lần 1 | I11: Lần 2 | J11: Lần 3 | K11: Lần 1 | L11: Lần 2 | M11: Lần 3 | N11: Lần 1 | O11: Lần 2 | P11: Lần 3
A12: =IF(AND(D12="",D12=""),"",$D$3&"_"&ROW()-11-COUNTBLANK($D$12:D12)) | B12: Chức năng 1.1: Màn hình thông báo
A13: =IF(AND(D13="",D13=""),"",$D$3&"_"&ROW()-11-COUNTBLANK($D$12:D13)) | B13: Giao diện (Phần này viết các trường hợp kiểm thử cho giao diên chung và các giao diện cho các control)
A14: =IF(AND(D14="",D14=""),"",$D$3&"_"&ROW()-11-COUNTBLANK($D$12:D14)) | B14: Giao diện chung
A15: =IF(AND(D15="",D15=""),"",$D$3&"_"&ROW()-11-COUNTBLANK($D$12:D15)) | B15: Kiểm tra hiển thị màn hình Thông báo | C15: pre: Chưa đăng nhập 1. Mở app 2. Click tab “Thông báo” | D15: 2. Điều hướng sang màn login | E15: P | Q15: =IF(OR(IF(G15="",IF(F15="",IF(E15="","",E15),F15),G15)="F",IF(J15="",IF(I15="",IF(H15="","",H15),I15),J15)="F",IF(M15="",IF(L15="",IF(K15="","",K15),L15),M15)="F",IF(P15="",IF(O15="",IF(N15="","",N15),O15),P15)="F")=TRUE,"F",IF(OR(IF(G15="",IF(F15="",IF(E15="","",E15),F15),G15)="PE",IF(J15="",IF(I15="",IF(H15="","",H15),I15),J15)="PE",IF(M15="",IF(L15="",IF(K15="","",K15),L15),M15)="PE",IF(P15="",IF(O15="",IF(N15="","",N15),O15),P15)="PE")=TRUE,"PE",IF(AND(IF(G15="",IF(F15="",IF(E15="","",E15),F15),G15)="",IF(J15="",IF(I15="",IF(H15="","",H15),I15),J15)="",IF(M15="",IF(L15="",IF(K15="","",K15),L15),M15)="",IF(P15="",IF(O15="",IF(N15="","",N15),O15),P15)="")=TRUE,"","P")))
A16: =IF(AND(D16="",D16=""),"",$D$3&"_"&ROW()-11-COUNTBLANK($D$12:D16)) | C16: pre: Đã đăng nhập 1. Mở app 2. Click tab “Thông báo” | D16: 2. Giao diện hiển thị gồm: - Hiển thị title “Thông báo” - Có button “Đánh dấu đọc tất cả” - Có các tab: Hệ thống / Giao dịch / Khuyến mãi - Có bottom navigation | E16: P | Q16: =IF(OR(IF(G16="",IF(F16="",IF(E16="","",E16),F16),G16)="F",IF(J16="",IF(I16="",IF(H16="","",H16),I16),J16)="F",IF(M16="",IF(L16="",IF(K16="","",K16),L16),M16)="F",IF(P16="",IF(O16="",IF(N16="","",N16),O16),P16)="F")=TRUE,"F",IF(OR(IF(G16="",IF(F16="",IF(E16="","",E16),F16),G16)="PE",IF(J16="",IF(I16="",IF(H16="","",H16),I16),J16)="PE",IF(M16="",IF(L16="",IF(K16="","",K16),L16),M16)="PE",IF(P16="",IF(O16="",IF(N16="","",N16),O16),P16)="PE")=TRUE,"PE",IF(AND(IF(G16="",IF(F16="",IF(E16="","",E16),F16),G16)="",IF(J16="",IF(I16="",IF(H16="","",H16),I16),J16)="",IF(M16="",IF(L16="",IF(K16="","",K16),L16),M16)="",IF(P16="",IF(O16="",IF(N16="","",N16),O16),P16)="")=TRUE,"","P")))
A17: =IF(AND(D17="",D17=""),"",$D$3&"_"&ROW()-11-COUNTBLANK($D$12:D17)) | C17: Hình ảnh Light mode | E17: P | Q17: =IF(OR(IF(G17="",IF(F17="",IF(E17="","",E17),F17),G17)="F",IF(J17="",IF(I17="",IF(H17="","",H17),I17),J17)="F",IF(M17="",IF(L17="",IF(K17="","",K17),L17),M17)="F",IF(P17="",IF(O17="",IF(N17="","",N17),O17),P17)="F")=TRUE,"F",IF(OR(IF(G17="",IF(F17="",IF(E17="","",E17),F17),G17)="PE",IF(J17="",IF(I17="",IF(H17="","",H17),I17),J17)="PE",IF(M17="",IF(L17="",IF(K17="","",K17),L17),M17)="PE",IF(P17="",IF(O17="",IF(N17="","",N17),O17),P17)="PE")=TRUE,"PE",IF(AND(IF(G17="",IF(F17="",IF(E17="","",E17),F17),G17)="",IF(J17="",IF(I17="",IF(H17="","",H17),I17),J17)="",IF(M17="",IF(L17="",IF(K17="","",K17),L17),M17)="",IF(P17="",IF(O17="",IF(N17="","",N17),O17),P17)="")=TRUE,"","P")))
A18: =IF(AND(D18="",D18=""),"",$D$3&"_"&ROW()-11-COUNTBLANK($D$12:D18)) | C18: Hình ảnh Dark mode | E18: P | Q18: =IF(OR(IF(G18="",IF(F18="",IF(E18="","",E18),F18),G18)="F",IF(J18="",IF(I18="",IF(H18="","",H18),I18),J18)="F",IF(M18="",IF(L18="",IF(K18="","",K18),L18),M18)="F",IF(P18="",IF(O18="",IF(N18="","",N18),O18),P18)="F")=TRUE,"F",IF(OR(IF(G18="",IF(F18="",IF(E18="","",E18),F18),G18)="PE",IF(J18="",IF(I18="",IF(H18="","",H18),I18),J18)="PE",IF(M18="",IF(L18="",IF(K18="","",K18),L18),M18)="PE",IF(P18="",IF(O18="",IF(N18="","",N18),O18),P18)="PE")=TRUE,"PE",IF(AND(IF(G18="",IF(F18="",IF(E18="","",E18),F18),G18)="",IF(J18="",IF(I18="",IF(H18="","",H18),I18),J18)="",IF(M18="",IF(L18="",IF(K18="","",K18),L18),M18)="",IF(P18="",IF(O18="",IF(N18="","",N18),O18),P18)="")=TRUE,"","P")))
A19: =IF(AND(D19="",D19=""),"",$D$3&"_"&ROW()-11-COUNTBLANK($D$12:D19)) | B19: Kiểm tra tổng thể giao diện màn hình | C19: 1. Kiểm tra bố cục, màu chữ, font chữ | D19: 1. Đúng bố cục tương xứng, màu sắc, font chữ đúng thiết kế | E19: P | Q19: =IF(OR(IF(G19="",IF(F19="",IF(E19="","",E19),F19),G19)="F",IF(J19="",IF(I19="",IF(H19="","",H19),I19),J19)="F",IF(M19="",IF(L19="",IF(K19="","",K19),L19),M19)="F",IF(P19="",IF(O19="",IF(N19="","",N19),O19),P19)="F")=TRUE,"F",IF(OR(IF(G19="",IF(F19="",IF(E19="","",E19),F19),G19)="PE",IF(J19="",IF(I19="",IF(H19="","",H19),I19),J19)="PE",IF(M19="",IF(L19="",IF(K19="","",K19),L19),M19)="PE",IF(P19="",IF(O19="",IF(N19="","",N19),O19),P19)="PE")=TRUE,"PE",IF(AND(IF(G19="",IF(F19="",IF(E19="","",E19),F19),G19)="",IF(J19="",IF(I19="",IF(H19="","",H19),I19),J19)="",IF(M19="",IF(L19="",IF(K19="","",K19),L19),M19)="",IF(P19="",IF(O19="",IF(N19="","",N19),O19),P19)="")=TRUE,"","P")))
A20: =IF(AND(D20="",D20=""),"",$D$3&"_"&ROW()-11-COUNTBLANK($D$12:D20)) | C20: 1. Kiểm tra label, textbox, button , lỗi chính tả | D20: 1. - Các label, textbox có độ dài, rộng và khoảng cách bằng nhau, không xô lệch - Các label sử dụng cùng 1 loại font, cỡ chữ, căn lề trái - Kiểm tra tất cả lỗi về chính tả, cấu trúc câu, ngữ pháp | E20: P | Q20: =IF(OR(IF(G20="",IF(F20="",IF(E20="","",E20),F20),G20)="F",IF(J20="",IF(I20="",IF(H20="","",H20),I20),J20)="F",IF(M20="",IF(L20="",IF(K20="","",K20),L20),M20)="F",IF(P20="",IF(O20="",IF(N20="","",N20),O20),P20)="F")=TRUE,"F",IF(OR(IF(G20="",IF(F20="",IF(E20="","",E20),F20),G20)="PE",IF(J20="",IF(I20="",IF(H20="","",H20),I20),J20)="PE",IF(M20="",IF(L20="",IF(K20="","",K20),L20),M20)="PE",IF(P20="",IF(O20="",IF(N20="","",N20),O20),P20)="PE")=TRUE,"PE",IF(AND(IF(G20="",IF(F20="",IF(E20="","",E20),F20),G20)="",IF(J20="",IF(I20="",IF(H20="","",H20),I20),J20)="",IF(M20="",IF(L20="",IF(K20="","",K20),L20),M20)="",IF(P20="",IF(O20="",IF(N20="","",N20),O20),P20)="")=TRUE,"","P")))
A21: =IF(AND(D21="",D21=""),"",$D$3&"_"&ROW()-11-COUNTBLANK($D$12:D21)) | B21: Kiểm tra hiển thị item thông báo | C21: 1. Quan sát 1 item | D21: 1. Giao diện hiển thị gồm: - Có icon/avatar bên trái - Có nội dung thông báo | E21: P | Q21: =IF(OR(IF(G21="",IF(F21="",IF(E21="","",E21),F21),G21)="F",IF(J21="",IF(I21="",IF(H21="","",H21),I21),J21)="F",IF(M21="",IF(L21="",IF(K21="","",K21),L21),M21)="F",IF(P21="",IF(O21="",IF(N21="","",N21),O21),P21)="F")=TRUE,"F",IF(OR(IF(G21="",IF(F21="",IF(E21="","",E21),F21),G21)="PE",IF(J21="",IF(I21="",IF(H21="","",H21),I21),J21)="PE",IF(M21="",IF(L21="",IF(K21="","",K21),L21),M21)="PE",IF(P21="",IF(O21="",IF(N21="","",N21),O21),P21)="PE")=TRUE,"PE",IF(AND(IF(G21="",IF(F21="",IF(E21="","",E21),F21),G21)="",IF(J21="",IF(I21="",IF(H21="","",H21),I21),J21)="",IF(M21="",IF(L21="",IF(K21="","",K21),L21),M21)="",IF(P21="",IF(O21="",IF(N21="","",N21),O21),P21)="")=TRUE,"","P")))
A22: =IF(AND(D22="",D22=""),"",$D$3&"_"&ROW()-11-COUNTBLANK($D$12:D22)) | B22: Kiểm tra tab active/inactive | C22: 1. Vào màn hình Thông báo 2. Quan sát các tab | D22: 1. - Tab active: nền màu + chữ nổi bật - Tab inactive: nền xám/viền | E22: P | Q22: =IF(OR(IF(G22="",IF(F22="",IF(E22="","",E22),F22),G22)="F",IF(J22="",IF(I22="",IF(H22="","",H22),I22),J22)="F",IF(M22="",IF(L22="",IF(K22="","",K22),L22),M22)="F",IF(P22="",IF(O22="",IF(N22="","",N22),O22),P22)="F")=TRUE,"F",IF(OR(IF(G22="",IF(F22="",IF(E22="","",E22),F22),G22)="PE",IF(J22="",IF(I22="",IF(H22="","",H22),I22),J22)="PE",IF(M22="",IF(L22="",IF(K22="","",K22),L22),M22)="PE",IF(P22="",IF(O22="",IF(N22="","",N22),O22),P22)="PE")=TRUE,"PE",IF(AND(IF(G22="",IF(F22="",IF(E22="","",E22),F22),G22)="",IF(J22="",IF(I22="",IF(H22="","",H22),I22),J22)="",IF(M22="",IF(L22="",IF(K22="","",K22),L22),M22)="",IF(P22="",IF(O22="",IF(N22="","",N22),O22),P22)="")=TRUE,"","P")))
A23: =IF(AND(D23="",D23=""),"",$D$3&"_"&ROW()-11-COUNTBLANK($D$12:D29)) | B23: Kiểm tra không có dữ liệu | C23: 1. Vào màn hình Thông báo 2. Quan sát item | D23: 2. Hiển thị "Không có thông báo" | E23: P | Q23: =IF(OR(IF(G23="",IF(F23="",IF(E23="","",E23),F23),G23)="F",IF(J23="",IF(I23="",IF(H23="","",H23),I23),J23)="F",IF(M23="",IF(L23="",IF(K23="","",K23),L23),M23)="F",IF(P23="",IF(O23="",IF(N23="","",N23),O23),P23)="F")=TRUE,"F",IF(OR(IF(G23="",IF(F23="",IF(E23="","",E23),F23),G23)="PE",IF(J23="",IF(I23="",IF(H23="","",H23),I23),J23)="PE",IF(M23="",IF(L23="",IF(K23="","",K23),L23),M23)="PE",IF(P23="",IF(O23="",IF(N23="","",N23),O23),P23)="PE")=TRUE,"PE",IF(AND(IF(G23="",IF(F23="",IF(E23="","",E23),F23),G23)="",IF(J23="",IF(I23="",IF(H23="","",H23),I23),J23)="",IF(M23="",IF(L23="",IF(K23="","",K23),L23),M23)="",IF(P23="",IF(O23="",IF(N23="","",N23),O23),P23)="")=TRUE,"","P")))
A24: =IF(AND(D24="",D24=""),"",$D$3&"_"&ROW()-11-COUNTBLANK($D$12:D26)) | B24: Kiểm tra scroll danh sách | C24: 1. Scroll lên xuống | D24: 1. Scroll mượt, không lag | E24: P | Q24: =IF(OR(IF(G24="",IF(F24="",IF(E24="","",E24),F24),G24)="F",IF(J24="",IF(I24="",IF(H24="","",H24),I24),J24)="F",IF(M24="",IF(L24="",IF(K24="","",K24),L24),M24)="F",IF(P24="",IF(O24="",IF(N24="","",N24),O24),P24)="F")=TRUE,"F",IF(OR(IF(G24="",IF(F24="",IF(E24="","",E24),F24),G24)="PE",IF(J24="",IF(I24="",IF(H24="","",H24),I24),J24)="PE",IF(M24="",IF(L24="",IF(K24="","",K24),L24),M24)="PE",IF(P24="",IF(O24="",IF(N24="","",N24),O24),P24)="PE")=TRUE,"PE",IF(AND(IF(G24="",IF(F24="",IF(E24="","",E24),F24),G24)="",IF(J24="",IF(I24="",IF(H24="","",H24),I24),J24)="",IF(M24="",IF(L24="",IF(K24="","",K24),L24),M24)="",IF(P24="",IF(O24="",IF(N24="","",N24),O24),P24)="")=TRUE,"","P")))
A25: =IF(AND(D25="",D25=""),"",$D$3&"_"&ROW()-11-COUNTBLANK($D$12:D25)) | B25: Kiểm tra ngắt kết nối mạng | C25: 1. Mở màn hình Thông báo 2. Tắt WiFi/4G | D25: 2. - Hiển thị màn hình no internet giống figma - Không crash | E25: P | Q25: =IF(OR(IF(G25="",IF(F25="",IF(E25="","",E25),F25),G25)="F",IF(J25="",IF(I25="",IF(H25="","",H25),I25),J25)="F",IF(M25="",IF(L25="",IF(K25="","",K25),L25),M25)="F",IF(P25="",IF(O25="",IF(N25="","",N25),O25),P25)="F")=TRUE,"F",IF(OR(IF(G25="",IF(F25="",IF(E25="","",E25),F25),G25)="PE",IF(J25="",IF(I25="",IF(H25="","",H25),I25),J25)="PE",IF(M25="",IF(L25="",IF(K25="","",K25),L25),M25)="PE",IF(P25="",IF(O25="",IF(N25="","",N25),O25),P25)="PE")=TRUE,"PE",IF(AND(IF(G25="",IF(F25="",IF(E25="","",E25),F25),G25)="",IF(J25="",IF(I25="",IF(H25="","",H25),I25),J25)="",IF(M25="",IF(L25="",IF(K25="","",K25),L25),M25)="",IF(P25="",IF(O25="",IF(N25="","",N25),O25),P25)="")=TRUE,"","P")))
